<think>
Okay, so I've got this Java code to analyze. Let me see what it's doing.

Looking at the Test8 class, there are two methods: compute and main. The compute method takes two integers a and b and returns the result of dividing a by b. Then in main, they're calling compute with 10 and 0, and printing the result.

Hmm, wait a minute. In Java, if you divide an integer by another integer that's zero, it throws an ArithmeticException: Division by zero. So when compute(10, 0) is called, it should throw an exception instead of returning something.

The code doesn't handle this exception, so the main method will crash with an error. The bug here is that there's no try-catch block around the call to compute, which means any division by zero will propagate up and cause the program to fail when run.
</think>

```json
[
    {
        "bug": "Division by zero",
        "line": 4,
        "reason": "Attempting to divide by zero in line 4 causes an ArithmeticException."
    }
]
```